Workbook

Sheet Income Statements
A1: HISTORICAL FINANCIALS
A2: INCOME STATEMENTS
A3: (in millions, except per-share amounts)
C5: Notes (1) (2) | E5: Notes (1) (2) | G5: Notes (1) (2) | I5: Notes (1) (2) | K5: Notes (1) (2) | M5: Notes (1) (2) | O5: Notes (1) (2) | Q5: Notes (1) (2) | S5: Notes (1) (2) | U5: Notes (1) (2)
C6: GAAP | E6: NON-GAAP | G6: GAAP | I6: NON-GAAP | K6: GAAP | M6: NON-GAAP | O6: GAAP | Q6: NON-GAAP | S6: GAAP | U6: NON-GAAP
C7: FY 2023 | E7: =$C7 -> FY 2023 | G7: FY 2023 | I7: =$C7 -> FY 2023 | K7: FY 2023 | M7: =$C7 -> FY 2023 | O7: FY 2023 | Q7: =$C7 -> FY 2023 | S7: FY 2023 | U7: =$C7 -> FY 2023
C8: Quarter Ended | E8: =C8 -> Quarter Ended | G8: Quarter Ended | I8: =G8 -> Quarter Ended | K8: Quarter Ended | M8: =K8 -> Quarter Ended | O8: Quarter Ended | Q8: =O8 -> Quarter Ended | S8: Year Ended | U8: =S8 -> Year Ended
C9: October 29, 2022 | E9: October 29, 2022 | G9: January 28, 2023 | I9: January 28, 2023 | K9: April 29, 2023 | M9: April 29, 2023 | O9: July 29, 2023 | Q9: July 29, 2023 | S9: July 29, 2023 | U9: July 29, 2023
A10: REVENUE:
B11: Product | C11: 10245 | E11: 10245 | G11: 10155 | I11: 10155 | K11: 11092 | M11: 11092 | O11: 11650 | Q11: 11650 | S11: =K11+O11+G11+C11 -> 43142 | U11: =M11+Q11+E11+I11 -> 43142
B12: Service | C12: 3387 | E12: 3387 | G12: 3437 | I12: 3437 | K12: 3479 | M12: 3479 | O12: 3553 | Q12: 3553 | S12: =K12+O12+G12+C12 -> 13856 | U12: =M12+Q12+I12+E12 -> 13856
B13: Total revenue | C13: =SUM(C11:C12) -> 13632 | E13: =SUM(E11:E12) -> 13632 | G13: =SUM(G11:G12) -> 13592 | I13: =SUM(I11:I12) -> 13592 | K13: =SUM(K11:K12) -> 14571 | M13: =SUM(M11:M12) -> 14571 | O13: =SUM(O11:O12) -> 15203 | Q13: =SUM(Q11:Q12) -> 15203 | S13: =SUM(S11:S12) -> 56998 | U13: =SUM(U11:U12) -> 56998
A15: COST OF SALES:
B16: Product (a) - (e) | C16: 4179 | E16: 3993 | G16: 4038 | I16: 3844 | K16: 4136 | M16: 3939 | O16: 4237 | Q16: 4024 | S16: =K16+O16+G16+C16 -> 16590 | U16: =M16+Q16+I16+E16 -> 15800
B17: Service (a) & (c) | C17: 1107 | E17: 1057 | G17: 1127 | I17: 1061 | K17: 1203 | M17: 1137 | O17: 1218 | Q17: 1155 | S17: =K17+O17+G17+C17 -> 4655 | U17: =M17+Q17+I17+E17 -> 4410
B18: Total cost of sales (a) - (e) | C18: =SUM(C16:C17) -> 5286 | E18: =SUM(E16:E17) -> 5050 | G18: =SUM(G16:G17) -> 5165 | I18: =SUM(I16:I17) -> 4905 | K18: =SUM(K16:K17) -> 5339 | M18: =SUM(M16:M17) -> 5076 | O18: =SUM(O16:O17) -> 5455 | Q18: =SUM(Q16:Q17) -> 5179 | S18: =SUM(S16:S17) -> 21245 | U18: =SUM(U16:U17) -> 20210
A20: GROSS MARGIN (a) - (d) | C20: =C13-C18 -> 8346 | E20: =E13-E18 -> 8582 | G20: =G13-G18 -> 8427 | I20: =I13-I18 -> 8687 | K20: =K13-K18 -> 9232 | M20: =M13-M18 -> 9495 | O20: =O13-O18 -> 9748 | Q20: =Q13-Q18 -> 10024 | S20: =S13-S18 -> 35753 | U20: =U13-U18 -> 36788
B21: Product gross margin percentage | C21: =(C11-C16)/C11 -> 0.5920937 | E21: =(E11-E16)/E11 -> 0.6102489 | G21: =(G11-G16)/G11 -> 0.60236337 | I21: =(I11-I16)/I11 -> 0.62146726 | K21: =(K11-K16)/K11 -> 0.62711864 | M21: =(M11-M16)/M11 -> 0.64487919 | O21: =(O11-O16)/O11 -> 0.63630901 | Q21: =(Q11-Q16)/Q11 -> 0.65459227 | S21: =(S11-S16)/S11 -> 0.61545594 | U21: =(U11-U16)/U11 -> 0.63376756
B22: Service gross margin percentage | C22: =(C12-C17)/C12 -> 0.67316209 | E22: =(E12-E17)/E12 -> 0.68792442 | G22: =(G12-G17)/G12 -> 0.67209776 | I22: =(I12-I17)/I12 -> 0.69130055 | K22: =(K12-K17)/K12 -> 0.65421098 | M22: =(M12-M17)/M12 -> 0.67318195 | O22: =(O12-O17)/O12 -> 0.65719111 | Q22: =(Q12-Q17)/Q12 -> 0.6749226 | S22: =(S12-S17)/S12 -> 0.66404446 | U22: =(U12-U17)/U12 -> 0.68172633
B23: Total gross margin percentage | C23: =(C13-C18)/C13 -> 0.61223592 | E23: =(E13-E18)/E13 -> 0.62954812 | G23: =(G13-G18)/G13 -> 0.61999706 | I23: =(I13-I18)/I13 -> 0.63912596 | K23: =(K13-K18)/K13 -> 0.63358726 | M23: =(M13-M18)/M13 -> 0.65163681 | O23: =(O13-O18)/O13 -> 0.64118924 | Q23: =(Q13-Q18)/Q13 -> 0.65934355 | S23: =(S13-S18)/S13 -> 0.62726762 | U23: =(U13-U18)/U13 -> 0.64542616
A25: OPERATING EXPENSES:
B26: Research and development (a) & (c) | C26: 1781 | E26: 1510 | G26: 1855 | I26: 1548 | K26: 1962 | M26: 1639 | O26: 1953 | Q26: 1639 | S26: =K26+O26+G26+C26 -> 7551 | U26: =M26+Q26+I26+E26 -> 6336
B27: Sales and marketing (a), & (c) & (d) | C27: 2391 | E27: 2237 | G27: 2384 | I27: 2216 | K27: 2526 | M27: 2349 | O27: 2579 | Q27: 2399 | S27: =K27+O27+G27+C27 -> 9880 | U27: =M27+Q27+I27+E27 -> 9201
B28: General and administrative (a), (c) & (d) | C28: 565 | E28: 497 | G28: 582 | I28: 509 | K28: 641 | M28: 566 | O28: 690 | Q28: 608 | S28: =K28+O28+G28+C28 -> 2478 | U28: =M28+Q28+I28+E28 -> 2180
B29: Amortization of purchased intangible assets (b) | C29: 71 | E29: 0 | G29: 71 | I29: 0 | K29: 70 | M29: 0 | O29: 70 | Q29: 0 | S29: =K29+O29+G29+C29 -> 282 | U29: =M29+Q29+I29+E29 -> 0
B30: Restructuring and other charges (f) | C30: -2 | E30: 0 | G30: 243 | I30: 0 | K30: 87 | M30: 0 | O30: 203 | Q30: 0 | S30: =K30+O30+G30+C30 -> 531 | U30: =M30+Q30+I30+E30 -> 0
B31: Total operating expenses (a) - (f) | C31: =SUM(C26:C30) -> 4806 | E31: =SUM(E26:E30) -> 4244 | G31: =SUM(G26:G30) -> 5135 | I31: =SUM(I26:I30) -> 4273 | K31: =SUM(K26:K30) -> 5286 | M31: =SUM(M26:M30) -> 4554 | O31: =SUM(O26:O30) -> 5495 | Q31: =SUM(Q26:Q30) -> 4646 | S31: =SUM(S26:S30) -> 20722 | U31: =SUM(U26:U30) -> 17717
B32: Operating expense as a percentage of revenue | C32: =C31/C13 -> 0.35255282 | E32: =E31/E13 -> 0.31132629 | G32: =G31/G13 -> 0.37779576 | I32: =I31/I13 -> 0.3143761 | K32: =K31/K13 -> 0.36277538 | M32: =M31/M13 -> 0.3125386 | O32: =O31/O13 -> 0.36144182 | Q32: =Q31/Q13 -> 0.30559758 | S32: =S31/S13 -> 0.36355662 | U32: =U31/U13 -> 0.31083547
A34: OPERATING INCOME (a) - (f) | C34: =C20-C31 -> 3540 | E34: =E20-E31 -> 4338 | G34: =G20-G31 -> 3292 | I34: =I20-I31 -> 4414 | K34: =K20-K31 -> 3946 | M34: =M20-M31 -> 4941 | O34: =O20-O31 -> 4253 | Q34: =Q20-Q31 -> 5378 | S34: =S20-S31 -> 15031 | U34: =U20-U31 -> 19071
B35: Operating income as a percentage of revenue | C35: =C34/C13 -> 0.2596831 | E35: =E34/E13 -> 0.31822183 | G35: =G34/G13 -> 0.24220129 | I35: =I34/I13 -> 0.32474985 | K35: =K34/K13 -> 0.27081189 | M35: =M34/M13 -> 0.33909821 | O35: =O34/O13 -> 0.27974742 | Q35: =Q34/Q13 -> 0.35374597 | S35: =S34/S13 -> 0.26371101 | U35: =U34/U13 -> 0.33459069
A37: Interest income | C37: 169 | E37: 169 | G37: 219 | I37: 219 | K37: 262 | M37: 262 | O37: 312 | Q37: 312 | S37: =K37+O37+G37+C37 -> 962 | U37: =M37+Q37+I37+E37 -> 962
A38: Interest expense | C38: -100 | E38: -100 | G38: -107 | I38: -107 | K38: -109 | M38: -109 | O38: -111 | Q38: -111 | S38: =K38+O38+G38+C38 -> -427 | U38: =M38+Q38+I38+E38 -> -427
C39: -134 | E39: -25 | G39: 11 | I39: -33 | K39: -142 | M39: -19 | O39: 17 | Q39: -38 | S39: =K39+O39+G39+C39 -> -248 | U39: =Q39+M39+I39+E39 -> -115
B40: Interest and other income (loss), net | C40: =SUM(C37:C39) -> -65 | E40: =SUM(E37:E39) -> 44 | G40: =SUM(G37:G39) -> 123 | I40: =SUM(I37:I39) -> 79 | K40: =SUM(K37:K39) -> 11 | M40: =SUM(M37:M39) -> 134 | O40: =SUM(O37:O39) -> 218 | Q40: =SUM(Q37:Q39) -> 163 | S40: =SUM(S37:S39) -> 287 | U40: =SUM(U37:U39) -> 420
A42: INCOME BEFORE PROVISION FOR INCOME TAXES (a) - (g) | C42: =C34+C40 -> 3475 | E42: =E34+E40 -> 4382 | G42: =G34+G40 -> 3415 | I42: =I34+I40 -> 4493 | K42: =K34+K40 -> 3957 | M42: =M34+M40 -> 5075 | O42: =O34+O40 -> 4471 | Q42: =Q34+Q40 -> 5541 | S42: =S34+S40 -> 15318 | U42: =U34+U40 -> 19491
A44: Provision for income taxes (h) - (i) | C44: 805 | E44: 833 | G44: 642 | I44: 854 | K44: 745 | M44: 964 | O44: 513 | Q44: 861 | S44: =K44+O44+G44+C44 -> 2705 | U44: =M44+Q44+I44+E44 -> 3512
A46: NET INCOME (a) - (i) | C46: 2670 | E46: =E42-E44 -> 3549 | G46: =G42-G44 -> 2773 | I46: =I42-I44 -> 3639 | K46: =K42-K44 -> 3212 | M46: =M42-M44 -> 4111 | O46: =O42-O44 -> 3958 | Q46: =Q42-Q44 -> 4680 | S46: =S42-S44 -> 12613 | U46: =U42-U44 -> 15979
A48: Net income per share:
A49: Basic (a) - (i) | C49: =IFERROR(C46/C54," ") -> 0.64995131 | E49: =IFERROR(E46/E54," ") | G49: =IFERROR(G46/G54," ") -> 0.67584694 | I49: =IFERROR(I46/I54," ") | K49: =IFERROR(K46/K54," ") -> 0.78552213 | M49: =IFERROR(M46/M54," ") | O49: =IFERROR(O46/O54," ") -> 0.97224269 | Q49: =IFERROR(Q46/Q54," ") | S49: =IFERROR(S46/S54," ") -> 3.0816027 | U49: =IFERROR(U46/U54," ")
A51: Diluted (a) - (i) | C51: =IFERROR(C46/C56," ") -> 0.64868805 | E51: =IFERROR(E46/E56," ") -> 0.8622449 | G51: =IFERROR(G46/G56," ") -> 0.67371234 | I51: =IFERROR(I46/I56," ") -> 0.88411079 | K51: =IFERROR(K46/K56," ") -> 0.78150852 | M51: =IFERROR(M46/M56," ") -> 1.0002433 | O51: =IFERROR(O46/O56," ") -> 0.96701686 | Q51: =IFERROR(Q46/Q56," ") -> 1.1434156 | S51: =IFERROR(S46/S56," ") -> 3.0725944 | U51: =IFERROR(U46/U56," ") -> 3.89257
...

Sheet GAAP Recon Note 1
A1: INCOME STATEMENTS
A2: Note 1
A3: (in millions)
D5: ='Income Statements'!C7 -> FY 2023 | F5: ='Income Statements'!G7 -> FY 2023 | H5: ='Income Statements'!K7 -> FY 2023 | I5: ='Income Statements'!P7 -> 0 | J5: ='Income Statements'!O7 -> FY 2023 | K5: ='Income Statements'!R7 -> 0 | L5: ='Income Statements'!Q7 -> FY 2023
D6: ='Income Statements'!C8 -> Quarter Ended | F6: ='Income Statements'!G8 -> Quarter Ended | H6: ='Income Statements'!K8 -> Quarter Ended | I6: ='Income Statements'!P8 -> 0 | J6: ='Income Statements'!O8 -> Quarter Ended | K6: ='Income Statements'!R8 -> 0 | L6: Year Ended
D7: ='Income Statements'!C9 -> October 29, 2022 | F7: ='Income Statements'!G9 -> January 28, 2023 | H7: ='Income Statements'!K9 -> April 29, 2023 | I7: ='Income Statements'!P9 -> 0 | J7: ='Income Statements'!O9 -> July 29, 2023 | K7: ='Income Statements'!R9 -> 0 | L7: ='Income Statements'!Q9 -> July 29, 2023
A8: A reconciliation between net income on a GAAP basis and non-GAAP net income including items (a) to (i) is as follows:
A10: GAAP net income | D10: ='Income Statements'!C46 -> 2670 | F10: ='Income Statements'!G46 -> 2773 | H10: ='Income Statements'!K46 -> 3212 | I10: ='Income Statements'!P46 -> 0 | J10: ='Income Statements'!O46 -> 3958 | K10: ='Income Statements'!R46 -> 0 | L10: ='Income Statements'!S46 -> 12613
A11: (a) | B11: Share-based compensation expense | D11: ='GAAP Recon Note 2'!N11 -> 496 | F11: ='GAAP Recon Note 2'!N21 -> 604 | H11: ='GAAP Recon Note 2'!N31 -> 624 | I11: ='GAAP Recon Note 2'!O31 -> 0 | J11: ='GAAP Recon Note 2'!N41 -> 623 | K11: ='GAAP Recon Note 2'!Q31 -> 0 | L11: ='GAAP Recon Note 2'!N51 -> 2347
A12: (b) | B12: Amortization of acquisition-related intangible assets | D12: ='GAAP Recon Note 2'!N12 -> 224 | F12: ='GAAP Recon Note 2'!N22 -> 224 | H12: ='GAAP Recon Note 2'!N32 -> 226 | I12: ='GAAP Recon Note 2'!O32 -> 0 | J12: ='GAAP Recon Note 2'!N42 -> 238 | K12: ='GAAP Recon Note 2'!Q32 -> 0 | L12: ='GAAP Recon Note 2'!N52 -> 912
A13: (c) | B13: Other acquisition-related/divestiture costs | D13: ='GAAP Recon Note 2'!N13 -> 77 | F13: ='GAAP Recon Note 2'!N23 -> 49 | H13: ='GAAP Recon Note 2'!N33 -> 56 | I13: ='GAAP Recon Note 2'!O33 -> 0 | J13: ='GAAP Recon Note 2'!N43 -> 77 | K13: ='GAAP Recon Note 2'!Q33 -> 0 | L13: ='GAAP Recon Note 2'!N53 -> 259
A14: (d) | B14: Russia-Ukraine war costs | D14: ='GAAP Recon Note 2'!N14 -> 3 | F14: ='GAAP Recon Note 2'!N24 -> 2 | H14: ='GAAP Recon Note 2'!N34 -> 2 | I14: ='GAAP Recon Note 2'!O34 -> 0 | J14: ='GAAP Recon Note 2'!N44 -> -7 | K14: ='GAAP Recon Note 2'!Q34 -> 0 | L14: ='GAAP Recon Note 2'!N54 -> 0
A15: (e) | B15: Supplier component remediation charge (adjustment) | D15: ='GAAP Recon Note 2'!N15 -> 0 | F15: ='GAAP Recon Note 2'!N25 -> 0 | H15: ='GAAP Recon Note 2'!N35 -> 0 | J15: ='GAAP Recon Note 2'!N45 -> -9 | L15: ='GAAP Recon Note 2'!N55 -> -9
A16: (f) | B16: Significant asset impairments and restructurings | D16: ='GAAP Recon Note 2'!N16 -> -2 | F16: ='GAAP Recon Note 2'!N26 -> 243 | H16: ='GAAP Recon Note 2'!N36 -> 87 | I16: ='GAAP Recon Note 2'!O36 -> 0 | J16: ='GAAP Recon Note 2'!N46 -> 203 | K16: ='GAAP Recon Note 2'!Q36 -> 0 | L16: ='GAAP Recon Note 2'!N56 -> 531
A17: (g) | B17: Gains and losses on equity investments | D17: ='GAAP Recon Note 2'!N17 -> 109 | F17: ='GAAP Recon Note 2'!N27 -> -44 | H17: ='GAAP Recon Note 2'!N37 -> 123 | I17: ='GAAP Recon Note 2'!O37 -> 0 | J17: ='GAAP Recon Note 2'!N47 -> -55 | K17: ='GAAP Recon Note 2'!Q37 -> 0 | L17: ='GAAP Recon Note 2'!N57 -> 133
A18: Total adjustments to GAAP income before provision for income taxes | D18: =SUM(D11:D17) -> 907 | F18: =SUM(F11:F17) -> 1078 | H18: =SUM(H11:H17) -> 1118 | I18: =SUM(I11:I17) -> 0 | J18: =SUM(J11:J17) -> 1070 | K18: =SUM(K11:K17) -> 0 | L18: =SUM(L11:L17) -> 4173
A19: (h) | B19: Income tax effect | D19: -192 | F19: -212 | H19: -219 | I19: =G19+E19 -> 0 | J19: -215 | K19: =I19+G19 -> 0 | L19: =F19+D19+H19+J19 -> -838
A20: (i) | B20: Significant tax matters | D20: 164 | F20: 0 | H20: 0 | I20: =G20+E20 -> 0 | J20: -133 | K20: =I20+G20 -> 0 | L20: =F20+D20+H20+J20 -> 31
A21: Total adjustments to GAAP provision for income taxes | D21: =SUM(D19:D20) -> -28 | F21: =SUM(F19:F20) -> -212 | H21: =SUM(H19:H20) -> -219 | I21: =SUM(I19:I20) -> 0 | J21: =SUM(J19:J20) -> -348 | K21: =SUM(K19:K20) -> 0 | L21: =SUM(L19:L20) -> -807
A23: Non-GAAP net income | D23: =D10+D18+D21 -> 3549 | F23: =F10+F18+F21 -> 3639 | H23: =H10+H18+H21 -> 4111 | I23: =I10+I18+I21 -> 0 | J23: =J10+J18+J21 -> 4680 | K23: =K10+K18+K21 -> 0 | L23: =L10+L18+L21 -> 15979

Sheet GAAP Recon Note 2
A1: INCOME STATEMENTS
A2: Note 2
A3: (in millions)
E5: COGS | H5: Operating Expense | M5: OI&E
H6: Research and Development | I6: Sales and Marketing | J6: General and Administrative | K6: Amortization of Purchased Intangible Assets | L6: Restructuring and Other Charges | M6: Other Income (Expense) | N6: Total
E7: Product | F7: Service
C8: Items (a) to (g) in note 1 are allocated as follows:
A10: Items | C10: Q1'23
A11: (a) | C11: Share-based compensation expense | E11: 31 | F11: 50 | H11: 204 | I11: 153 | J11: 58 | K11: 0 | L11: 0 | M11: 0 | N11: =SUM(E11:M11) -> 496
A12: (b) | C12: Amortization of acquisition-related intangible assets | E12: 153 | F12: 0 | H12: 0 | I12: 0 | J12: 0 | K12: 71 | L12: 0 | M12: 0 | N12: =SUM(E12:M12) -> 224
A13: (c) | C13: Other acquisition-related/divestiture costs | E13: 2 | F13: 0 | H13: 67 | I13: 2 | J13: 6 | K13: 0 | L13: 0 | M13: 0 | N13: =SUM(E13:M13) -> 77
A14: (d) | C14: Russia-Ukraine war costs | E14: 0 | F14: 0 | H14: 0 | I14: -1 | J14: 4 | K14: 0 | L14: 0 | M14: 0 | N14: =SUM(E14:M14) -> 3
A15: (e) | C15: Supplier component remediation charge (adjustment) | E15: 0 | F15: 0 | H15: 0 | I15: 0 | J15: 0 | K15: 0 | L15: 0 | M15: 0 | N15: =SUM(E15:M15) -> 0
A16: (f) | C16: Significant asset impairments and restructurings | E16: 0 | F16: 0 | H16: 0 | I16: 0 | J16: 0 | K16: 0 | L16: -2 | M16: 0 | N16: =SUM(E16:M16) -> -2
A17: (g) | C17: Gains and losses on equity investments | E17: 0 | F17: 0 | H17: 0 | I17: 0 | J17: 0 | K17: 0 | L17: 0 | M17: 109 | N17: =SUM(E17:M17) -> 109
C18: Total | E18: =SUM(E11:E17) -> 186 | F18: =SUM(F11:F17) -> 50 | H18: =SUM(H11:H17) -> 271 | I18: =SUM(I11:I17) -> 154 | J18: =SUM(J11:J17) -> 68 | K18: =SUM(K11:K17) -> 71 | L18: =SUM(L11:L17) -> -2 | M18: =SUM(M11:M17) -> 109 | N18: =SUM(E18:M18) -> 907
A20: Items | C20: Q2'23
A21: (a) | C21: Share-based compensation expense | E21: 40 | F21: 66 | H21: 261 | I21: 166 | J21: 71 | K21: 0 | L21: 0 | M21: 0 | N21: =SUM(E21:M21) -> 604
A22: (b) | C22: Amortization of acquisition-related intangible assets | E22: 153 | F22: 0 | H22: 0 | I22: 0 | J22: 0 | K22: 71 | L22: 0 | M22: 0 | N22: =SUM(E22:M22) -> 224
A23: (c) | C23: Other acquisition-related/divestiture costs | E23: 1 | F23: 0 | H23: 46 | I23: 1 | J23: 1 | K23: 0 | L23: 0 | M23: 0 | N23: =SUM(E23:M23) -> 49
A24: (d) | C24: Russia-Ukraine war costs | E24: 0 | F24: 0 | H24: 0 | I24: 1 | J24: 1 | K24: 0 | L24: 0 | M24: 0 | N24: =SUM(E24:M24) -> 2
A25: (e) | C25: Supplier component remediation charge (adjustment) | E25: 0 | F25: 0 | H25: 0 | I25: 0 | J25: 0 | K25: 0 | L25: 0 | M25: 0 | N25: =SUM(E25:M25) -> 0
A26: (f) | C26: Significant asset impairments and restructurings | E26: 0 | F26: 0 | H26: 0 | I26: 0 | J26: 0 | K26: 0 | L26: 243 | M26: 0 | N26: =SUM(E26:M26) -> 243
A27: (g) | C27: Gains and losses on equity investments | E27: 0 | F27: 0 | H27: 0 | I27: 0 | J27: 0 | K27: 0 | L27: 0 | M27: -44 | N27: =SUM(E27:M27) -> -44
C28: Total | E28: =SUM(E21:E27) -> 194 | F28: =SUM(F21:F27) -> 66 | H28: =SUM(H21:H27) -> 307 | I28: =SUM(I21:I27) -> 168 | J28: =SUM(J21:J27) -> 73 | K28: =SUM(K21:K27) -> 71 | L28: =SUM(L21:L27) -> 243 | M28: =SUM(M21:M27) -> -44 | N28: =SUM(E28:M28) -> 1078
A30: Items | C30: Q3'23
A31: (a) | C31: Share-based compensation expense | E31: 40 | F31: 66 | H31: 272 | I31: 175 | J31: 71 | K31: 0 | L31: 0 | M31: 0 | N31: =SUM(E31:M31) -> 624
A32: (b) | C32: Amortization of acquisition-related intangible assets | E32: 156 | F32: 0 | H32: 0 | I32: 0 | J32: 0 | K32: 70 | L32: 0 | M32: 0 | N32: =SUM(E32:M32) -> 226
A33: (c) | C33: Other acquisition-related/divestiture costs | E33: 1 | F33: 0 | H33: 51 | I33: 1 | J33: 3 | K33: 0 | L33: 0 | M33: 0 | N33: =SUM(E33:M33) -> 56
A34: (d) | C34: Russia-Ukraine war costs | E34: 0 | F34: 0 | H34: 0 | I34: 1 | J34: 1 | K34: 0 | L34: 0 | M34: 0 | N34: =SUM(E34:M34) -> 2
A35: (e) | C35: Supplier component remediation charge (adjustment) | E35: 0 | F35: 0 | H35: 0 | I35: 0 | J35: 0 | K35: 0 | L35: 0 | M35: 0 | N35: =SUM(E35:M35) -> 0
A36: (f) | C36: Significant asset impairments and restructurings | E36: 0 | F36: 0 | H36: 0 | I36: 0 | J36: 0 | K36: 0 | L36: 87 | M36: 0 | N36: =SUM(E36:M36) -> 87
A37: (g) | C37: Gains and losses on equity investments | E37: 0 | F37: 0 | H37: 0 | I37: 0 | J37: 0 | K37: 0 | L37: 0 | M37: 123 | N37: =SUM(E37:M37) -> 123
C38: Total | E38: =SUM(E31:E37) -> 197 | F38: =SUM(F31:F37) -> 66 | H38: =SUM(H31:H37) -> 323 | I38: =SUM(I31:I37) -> 177 | J38: =SUM(J31:J37) -> 75 | K38: =SUM(K31:K37) -> 70 | L38: =SUM(L31:L37) -> 87 | M38: =SUM(M31:M37) -> 123 | N38: =SUM(E38:M38) -> 1118
A40: Items | C40: Q4'23
A41: (a) | C41: Share-based compensation expense | E41: 40 | F41: 63 | G41: =G11+G21+G31 -> 0 | H41: 271 | I41: 179 | J41: 70 | K41: 0 | L41: 0 | M41: 0 | N41: =SUM(E41:M41) -> 623
A42: (b) | C42: Amortization of acquisition-related intangible assets | E42: 168 | F42: 0 | G42: =G12+G22+G32 -> 0 | H42: 0 | I42: 0 | J42: 0 | K42: 70 | L42: 0 | M42: 0 | N42: =SUM(E42:M42) -> 238
A43: (c) | C43: Other acquisition-related/divestiture costs | E43: 14 | F43: 0 | G43: =G13+G23+G33 -> 0 | H43: 43 | I43: 1 | J43: 19 | K43: 0 | L43: 0 | M43: 0 | N43: =SUM(E43:M43) -> 77
A44: (d) | C44: Russia-Ukraine war costs | E44: 0 | F44: 0 | G44: =G14+G24+G34 -> 0 | H44: 0 | I44: 0 | J44: -7 | K44: 0 | L44: 0 | M44: 0 | N44: =SUM(E44:M44) -> -7
A45: (e) | C45: Supplier component remediation charge (adjustment) | E45: -9 | F45: 0 | H45: 0 | I45: 0 | J45: 0 | K45: 0 | L45: 0 | M45: 0 | N45: =SUM(E45:M45) -> -9
...
